Workbook

Sheet Assumptions
A1: Synthetic IFRS 17-related assumptions
A2: Editable inputs | B2: Value | C2: Unit / use | H2: Currency | I2: EUR rate | K2: Product | L2: Loss ratio
A3: Discount rate | B3: 0.035 | C3: Interest accretion
A4: Service movement rate | B4: 0.08 | C4: Claims and service movement | H4: EUR | I4: 1 | K4: Term Life | L4: 0.62
A5: Expense loading | B5: 0.02 | C5: Expense movement | H5: GBP | I5: 1.15 | K5: Annuity | L5: 0.7
A6: Assumption strengthening rate | B6: 0.015 | C6: Reserve strengthening | K6: Savings | L6: 0.55
A7: Reporting FX baseline | B7: 1 | C7: FX movement baseline
A8: Rounding significance | B8: 100 | C8: CEILING/FLOOR controls
A9: Upper display precision | B9: 0 | C9: ROUNDUP control
A10: Lower display precision | B10: 0 | C10: ROUNDDOWN control
A11: Zero value | B11: 0 | C11: Explicit zero branch
A12: Exposure unit divisor | B12: 100000 | C12: Whole exposure units

Sheet CohortData
A1: Synthetic policy cohort data and calculated attributes
A2: Aurora Mutual Life SE (synthetic); 2025-Q4; reporting currency EUR
A3: Cohort ID | B3: Entity | C3: Product | D3: Currency | E3: Premium | F3: Expected claims input | G3: Opening reserve input | H3: Included | I3: FX to EUR | J3: Product index | K3: Loss ratio | L3: Modelled claims | M3: Absolute input variance | N3: Exposure units
A4: SYN-0001 | B4: Aurora Mutual Life SE (synthetic) | C4: Term Life | D4: EUR | E4: 427000 | F4: 264740 | G4: 158844 | H4: =TRUE() -> 1 | I4: =VLOOKUP(D4,Assumptions!$H$4:$I$5,2,FALSE()) -> 1 | J4: =MATCH(C4,Assumptions!$K$4:$K$6,0) -> 1 | K4: =INDEX(Assumptions!$L$4:$L$6,J4) -> 0.62 | L4: =IF(H4,ROUND(E4*K4,2),Assumptions!$B$11) -> 264740 | M4: =ABS(F4-L4) -> 0 | N4: =INT(E4/Assumptions!$B$12) -> 4
A5: SYN-0002 | B5: Aurora Mutual Life SE (synthetic) | C5: Annuity | D5: EUR | E5: 157000 | F5: 109900 | G5: 65940 | H5: =TRUE() -> 1 | I5: =VLOOKUP(D5,Assumptions!$H$4:$I$5,2,FALSE()) -> 1 | J5: =MATCH(C5,Assumptions!$K$4:$K$6,0) -> 2 | K5: =INDEX(Assumptions!$L$4:$L$6,J5) -> 0.7 | L5: =IF(H5,ROUND(E5*K5,2),Assumptions!$B$11) -> 109900 | M5: =ABS(F5-L5) -> 0 | N5: =INT(E5/Assumptions!$B$12) -> 1
A6: SYN-0003 | B6: Aurora Mutual Life SE (synthetic) | C6: Savings | D6: EUR | E6: 112000 | F6: 61600 | G6: 36960 | H6: =TRUE() -> 1 | I6: =VLOOKUP(D6,Assumptions!$H$4:$I$5,2,FALSE()) -> 1 | J6: =MATCH(C6,Assumptions!$K$4:$K$6,0) -> 3 | K6: =INDEX(Assumptions!$L$4:$L$6,J6) -> 0.55 | L6: =IF(H6,ROUND(E6*K6,2),Assumptions!$B$11) -> 61600 | M6: =ABS(F6-L6) -> 0 | N6: =INT(E6/Assumptions!$B$12) -> 1
A7: SYN-0004 | B7: Aurora Mutual Life SE (synthetic) | C7: Term Life | D7: GBP | E7: 479000 | F7: 296980 | G7: 178188 | H7: =TRUE() -> 1 | I7: =VLOOKUP(D7,Assumptions!$H$4:$I$5,2,FALSE()) -> 1.15 | J7: =MATCH(C7,Assumptions!$K$4:$K$6,0) -> 1 | K7: =INDEX(Assumptions!$L$4:$L$6,J7) -> 0.62 | L7: =IF(H7,ROUND(E7*K7,2),Assumptions!$B$11) -> 296980 | M7: =ABS(F7-L7) -> 0 | N7: =INT(E7/Assumptions!$B$12) -> 4
A8: SYN-0005 | B8: Aurora Mutual Life SE (synthetic) | C8: Annuity | D8: EUR | E8: 240000 | F8: 168000 | G8: 100800 | H8: =TRUE() -> 1 | I8: =VLOOKUP(D8,Assumptions!$H$4:$I$5,2,FALSE()) -> 1 | J8: =MATCH(C8,Assumptions!$K$4:$K$6,0) -> 2 | K8: =INDEX(Assumptions!$L$4:$L$6,J8) -> 0.7 | L8: =IF(H8,ROUND(E8*K8,2),Assumptions!$B$11) -> 168000 | M8: =ABS(F8-L8) -> 0 | N8: =INT(E8/Assumptions!$B$12) -> 2
A9: SYN-0006 | B9: Aurora Mutual Life SE (synthetic) | C9: Savings | D9: EUR | E9: 225000 | F9: 123750 | G9: 74250 | H9: =TRUE() -> 1 | I9: =VLOOKUP(D9,Assumptions!$H$4:$I$5,2,FALSE()) -> 1 | J9: =MATCH(C9,Assumptions!$K$4:$K$6,0) -> 3 | K9: =INDEX(Assumptions!$L$4:$L$6,J9) -> 0.55 | L9: =IF(H9,ROUND(E9*K9,2),Assumptions!$B$11) -> 123750 | M9: =ABS(F9-L9) -> 0 | N9: =INT(E9/Assumptions!$B$12) -> 2
A10: SYN-0007 | B10: Aurora Mutual Life SE (synthetic) | C10: Term Life | D10: EUR | E10: 214000 | F10: 132680 | G10: 79608 | H10: =TRUE() -> 1 | I10: =VLOOKUP(D10,Assumptions!$H$4:$I$5,2,FALSE()) -> 1 | J10: =MATCH(C10,Assumptions!$K$4:$K$6,0) -> 1 | K10: =INDEX(Assumptions!$L$4:$L$6,J10) -> 0.62 | L10: =IF(H10,ROUND(E10*K10,2),Assumptions!$B$11) -> 132680 | M10: =ABS(F10-L10) -> 0 | N10: =INT(E10/Assumptions!$B$12) -> 2
A11: SYN-0008 | B11: Aurora Mutual Life SE (synthetic) | C11: Annuity | D11: GBP | E11: 171000 | F11: 119700 | G11: 71820 | H11: =TRUE() -> 1 | I11: =VLOOKUP(D11,Assumptions!$H$4:$I$5,2,FALSE()) -> 1.15 | J11: =MATCH(C11,Assumptions!$K$4:$K$6,0) -> 2 | K11: =INDEX(Assumptions!$L$4:$L$6,J11) -> 0.7 | L11: =IF(H11,ROUND(E11*K11,2),Assumptions!$B$11) -> 119700 | M11: =ABS(F11-L11) -> 0 | N11: =INT(E11/Assumptions!$B$12) -> 1
A12: SYN-0009 | B12: Aurora Mutual Life SE (synthetic) | C12: Savings | D12: EUR | E12: 477000 | F12: 262350 | G12: 157410 | H12: =TRUE() -> 1 | I12: =VLOOKUP(D12,Assumptions!$H$4:$I$5,2,FALSE()) -> 1 | J12: =MATCH(C12,Assumptions!$K$4:$K$6,0) -> 3 | K12: =INDEX(Assumptions!$L$4:$L$6,J12) -> 0.55 | L12: =IF(H12,ROUND(E12*K12,2),Assumptions!$B$11) -> 262350 | M12: =ABS(F12-L12) -> 0 | N12: =INT(E12/Assumptions!$B$12) -> 4
A13: SYN-0010 | B13: Aurora Mutual Life SE (synthetic) | C13: Term Life | D13: EUR | E13: 152000 | F13: 94240 | G13: 56544 | H13: =TRUE() -> 1 | I13: =VLOOKUP(D13,Assumptions!$H$4:$I$5,2,FALSE()) -> 1 | J13: =MATCH(C13,Assumptions!$K$4:$K$6,0) -> 1 | K13: =INDEX(Assumptions!$L$4:$L$6,J13) -> 0.62 | L13: =IF(H13,ROUND(E13*K13,2),Assumptions!$B$11) -> 94240 | M13: =ABS(F13-L13) -> 0 | N13: =INT(E13/Assumptions!$B$12) -> 1
A14: SYN-0011 | B14: Aurora Mutual Life SE (synthetic) | C14: Annuity | D14: EUR | E14: 446000 | F14: 312200 | G14: 187320 | H14: =TRUE() -> 1 | I14: =VLOOKUP(D14,Assumptions!$H$4:$I$5,2,FALSE()) -> 1 | J14: =MATCH(C14,Assumptions!$K$4:$K$6,0) -> 2 | K14: =INDEX(Assumptions!$L$4:$L$6,J14) -> 0.7 | L14: =IF(H14,ROUND(E14*K14,2),Assumptions!$B$11) -> 312200 | M14: =ABS(F14-L14) -> 0 | N14: =INT(E14/Assumptions!$B$12) -> 4
A15: SYN-0012 | B15: Aurora Mutual Life SE (synthetic) | C15: Savings | D15: GBP | E15: 479000 | F15: 263450 | G15: 158070 | H15: =TRUE() -> 1 | I15: =VLOOKUP(D15,Assumptions!$H$4:$I$5,2,FALSE()) -> 1.15 | J15: =MATCH(C15,Assumptions!$K$4:$K$6,0) -> 3 | K15: =INDEX(Assumptions!$L$4:$L$6,J15) -> 0.55 | L15: =IF(H15,ROUND(E15*K15,2),Assumptions!$B$11) -> 263450 | M15: =ABS(F15-L15) -> 0 | N15: =INT(E15/Assumptions!$B$12) -> 4
... A19: SYN-0016 | B19: Aurora Mutual Life SE (synthetic) | C19: Term Life | D19: GBP | E19: 316000 | F19: 195920 | G19: 117552 | H19: =TRUE() -> 1 | I19: =VLOOKUP(D19,Assumptions!$H$4:$I$5,2,FALSE()) -> 1.15 | J19: =MATCH(C19,Assumptions!$K$4:$K$6,0) -> 1 | K19: =INDEX(Assumptions!$L$4:$L$6,J19) -> 0.62 | L19: =IF(H19,ROUND(E19*K19,2),Assumptions!$B$11) -> 195920 | M19: =ABS(F19-L19) -> 0 | N19: =INT(E19/Assumptions!$B$12) -> 3
A20: SYN-0017 | B20: Aurora Mutual Life SE (synthetic) | C20: Annuity | D20: EUR | E20: 116000 | F20: 81200 | G20: 48720 | H20: =FALSE() -> 0 | I20: =VLOOKUP(D20,Assumptions!$H$4:$I$5,2,FALSE()) -> 1 | J20: =MATCH(C20,Assumptions!$K$4:$K$6,0) -> 2 | K20: =INDEX(Assumptions!$L$4:$L$6,J20) -> 0.7 | L20: =IF(H20,ROUND(E20*K20,2),Assumptions!$B$11) -> 0 | M20: =ABS(F20-L20) -> 81200 | N20: =INT(E20/Assumptions!$B$12) -> 1
A21: SYN-0018 | B21: Aurora Mutual Life SE (synthetic) | C21: Savings | D21: EUR | E21: 115000 | F21: 63250 | G21: 37950 | H21: =TRUE() -> 1 | I21: =VLOOKUP(D21,Assumptions!$H$4:$I$5,2,FALSE()) -> 1 | J21: =MATCH(C21,Assumptions!$K$4:$K$6,0) -> 3 | K21: =INDEX(Assumptions!$L$4:$L$6,J21) -> 0.55 | L21: =IF(H21,ROUND(E21*K21,2),Assumptions!$B$11) -> 63250 | M21: =ABS(F21-L21) -> 0 | N21: =INT(E21/Assumptions!$B$12) -> 1
A22: SYN-0019 | B22: Aurora Mutual Life SE (synthetic) | C22: Term Life | D22: EUR | E22: 147000 | F22: 91140 | G22: 54684 | H22: =TRUE() -> 1 | I22: =VLOOKUP(D22,Assumptions!$H$4:$I$5,2,FALSE()) -> 1 | J22: =MATCH(C22,Assumptions!$K$4:$K$6,0) -> 1 | K22: =INDEX(Assumptions!$L$4:$L$6,J22) -> 0.62 | L22: =IF(H22,ROUND(E22*K22,2),Assumptions!$B$11) -> 91140 | M22: =ABS(F22-L22) -> 0 | N22: =INT(E22/Assumptions!$B$12) -> 1
A23: SYN-0020 | B23: Aurora Mutual Life SE (synthetic) | C23: Annuity | D23: GBP | E23: 211000 | F23: 147700 | G23: 88620 | H23: =TRUE() -> 1 | I23: =VLOOKUP(D23,Assumptions!$H$4:$I$5,2,FALSE()) -> 1.15 | J23: =MATCH(C23,Assumptions!$K$4:$K$6,0) -> 2 | K23: =INDEX(Assumptions!$L$4:$L$6,J23) -> 0.7 | L23: =IF(H23,ROUND(E23*K23,2),Assumptions!$B$11) -> 147700 | M23: =ABS(F23-L23) -> 0 | N23: =INT(E23/Assumptions!$B$12) -> 2
A24: SYN-0021 | B24: Aurora Mutual Life SE (synthetic) | C24: Savings | D24: EUR | E24: 219000 | F24: 120450 | G24: 72270 | H24: =TRUE() -> 1 | I24: =VLOOKUP(D24,Assumptions!$H$4:$I$5,2,FALSE()) -> 1 | J24: =MATCH(C24,Assumptions!$K$4:$K$6,0) -> 3 | K24: =INDEX(Assumptions!$L$4:$L$6,J24) -> 0.55 | L24: =IF(H24,ROUND(E24*K24,2),Assumptions!$B$11) -> 120450 | M24: =ABS(F24-L24) -> 0 | N24: =INT(E24/Assumptions!$B$12) -> 2
A25: SYN-0022 | B25: Aurora Mutual Life SE (synthetic) | C25: Term Life | D25: EUR | E25: 358000 | F25: 221960 | G25: 133176 | H25: =TRUE() -> 1 | I25: =VLOOKUP(D25,Assumptions!$H$4:$I$5,2,FALSE()) -> 1 | J25: =MATCH(C25,Assumptions!$K$4:$K$6,0) -> 1 | K25: =INDEX(Assumptions!$L$4:$L$6,J25) -> 0.62 | L25: =IF(H25,ROUND(E25*K25,2),Assumptions!$B$11) -> 221960 | M25: =ABS(F25-L25) -> 0 | N25: =INT(E25/Assumptions!$B$12) -> 3
A26: SYN-0023 | B26: Aurora Mutual Life SE (synthetic) | C26: Annuity | D26: EUR | E26: 408000 | F26: 285600 | G26: 171360 | H26: =TRUE() -> 1 | I26: =VLOOKUP(D26,Assumptions!$H$4:$I$5,2,FALSE()) -> 1 | J26: =MATCH(C26,Assumptions!$K$4:$K$6,0) -> 2 | K26: =INDEX(Assumptions!$L$4:$L$6,J26) -> 0.7 | L26: =IF(H26,ROUND(E26*K26,2),Assumptions!$B$11) -> 285600 | M26: =ABS(F26-L26) -> 0 | N26: =INT(E26/Assumptions!$B$12) -> 4
A27: SYN-0024 | B27: Aurora Mutual Life SE (synthetic) | C27: Savings | D27: GBP | E27: 113000 | F27: 62150 | G27: 37290 | H27: =TRUE() -> 1 | I27: =VLOOKUP(D27,Assumptions!$H$4:$I$5,2,FALSE()) -> 1.15 | J27: =MATCH(C27,Assumptions!$K$4:$K$6,0) -> 3 | K27: =INDEX(Assumptions!$L$4:$L$6,J27) -> 0.55 | L27: =IF(H27,ROUND(E27*K27,2),Assumptions!$B$11) -> 62150 | M27: =ABS(F27-L27) -> 0 | N27: =INT(E27/Assumptions!$B$12) -> 1
A28: SYN-0025 | B28: Aurora Mutual Life SE (synthetic) | C28: Term Life | D28: EUR | E28: 387000 | F28: 239940 | G28: 143964 | H28: =TRUE() -> 1 | I28: =VLOOKUP(D28,Assumptions!$H$4:$I$5,2,FALSE()) -> 1 | J28: =MATCH(C28,Assumptions!$K$4:$K$6,0) -> 1 | K28: =INDEX(Assumptions!$L$4:$L$6,J28) -> 0.62 | L28: =IF(H28,ROUND(E28*K28,2),Assumptions!$B$11) -> 239940 | M28: =ABS(F28-L28) -> 0 | N28: =INT(E28/Assumptions!$B$12) -> 3
A29: SYN-0026 | B29: Aurora Mutual Life SE (synthetic) | C29: Annuity | D29: EUR | E29: 201000 | F29: 140700 | G29: 84420 | H29: =TRUE() -> 1 | I29: =VLOOKUP(D29,Assumptions!$H$4:$I$5,2,FALSE()) -> 1 | J29: =MATCH(C29,Assumptions!$K$4:$K$6,0) -> 2 | K29: =INDEX(Assumptions!$L$4:$L$6,J29) -> 0.7 | L29: =IF(H29,ROUND(E29*K29,2),Assumptions!$B$11) -> 140700 | M29: =ABS(F29-L29) -> 0 | N29: =INT(E29/Assumptions!$B$12) -> 2
A30: SYN-0027 | B30: Aurora Mutual Life SE (synthetic) | C30: Savings | D30: EUR | E30: 466000 | F30: 256300 | G30: 153780 | H30: =TRUE() -> 1 | I30: =VLOOKUP(D30,Assumptions!$H$4:$I$5,2,FALSE()) -> 1 | J30: =MATCH(C30,Assumptions!$K$4:$K$6,0) -> 3 | K30: =INDEX(Assumptions!$L$4:$L$6,J30) -> 0.55 | L30: =IF(H30,ROUND(E30*K30,2),Assumptions!$B$11) -> 256300 | M30: =ABS(F30-L30) -> 0 | N30: =INT(E30/Assumptions!$B$12) -> 4
A31: SYN-0028 | B31: Aurora Mutual Life SE (synthetic) | C31: Term Life | D31: GBP | E31: 432000 | F31: 267840 | G31: 160704 | H31: =TRUE() -> 1 | I31: =VLOOKUP(D31,Assumptions!$H$4:$I$5,2,FALSE()) -> 1.15 | J31: =MATCH(C31,Assumptions!$K$4:$K$6,0) -> 1 | K31: =INDEX(Assumptions!$L$4:$L$6,J31) -> 0.62 | L31: =IF(H31,ROUND(E31*K31,2),Assumptions!$B$11) -> 267840 | M31: =ABS(F31-L31) -> 0 | N31: =INT(E31/Assumptions!$B$12) -> 4
A32: SYN-0029 | B32: Aurora Mutual Life SE (synthetic) | C32: Annuity | D32: EUR | E32: 459000 | F32: 321300 | G32: 192780 | H32: =TRUE() -> 1 | I32: =VLOOKUP(D32,Assumptions!$H$4:$I$5,2,FALSE()) -> 1 | J32: =MATCH(C32,Assumptions!$K$4:$K$6,0) -> 2 | K32: =INDEX(Assumptions!$L$4:$L$6,J32) -> 0.7 | L32: =IF(H32,ROUND(E32*K32,2),Assumptions!$B$11) -> 321300 | M32: =ABS(F32-L32) -> 0 | N32: =INT(E32/Assumptions!$B$12) -> 4
... A36: SYN-0033 | B36: Aurora Mutual Life SE (synthetic) | C36: Savings | D36: EUR | E36: 329000 | F36: 180950 | G36: 108570 | H36: =TRUE() -> 1 | I36: =VLOOKUP(D36,Assumptions!$H$4:$I$5,2,FALSE()) -> 1 | J36: =MATCH(C36,Assumptions!$K$4:$K$6,0) -> 3 | K36: =INDEX(Assumptions!$L$4:$L$6,J36) -> 0.55 | L36: =IF(H36,ROUND(E36*K36,2),Assumptions!$B$11) -> 180950 | M36: =ABS(F36-L36) -> 0 | N36: =INT(E36/Assumptions!$B$12) -> 3
A37: SYN-0034 | B37: Aurora Mutual Life SE (synthetic) | C37: Term Life | D37: EUR | E37: 401000 | F37: 248620 | G37: 149172 | H37: =FALSE() -> 0 | I37: =VLOOKUP(D37,Assumptions!$H$4:$I$5,2,FALSE()) -> 1 | J37: =MATCH(C37,Assumptions!$K$4:$K$6,0) -> 1 | K37: =INDEX(Assumptions!$L$4:$L$6,J37) -> 0.62 | L37: =IF(H37,ROUND(E37*K37,2),Assumptions!$B$11) -> 0 | M37: =ABS(F37-L37) -> 248620 | N37: =INT(E37/Assumptions!$B$12) -> 4
A38: SYN-0035 | B38: Aurora Mutual Life SE (synthetic) | C38: Annuity | D38: EUR | E38: 242000 | F38: 169400 | G38: 101640 | H38: =TRUE() -> 1 | I38: =VLOOKUP(D38,Assumptions!$H$4:$I$5,2,FALSE()) -> 1 | J38: =MATCH(C38,Assumptions!$K$4:$K$6,0) -> 2 | K38: =INDEX(Assumptions!$L$4:$L$6,J38) -> 0.7 | L38: =IF(H38,ROUND(E38*K38,2),Assumptions!$B$11) -> 169400 | M38: =ABS(F38-L38) -> 0 | N38: =INT(E38/Assumptions!$B$12) -> 2
A39: SYN-0036 | B39: Aurora Mutual Life SE (synthetic) | C39: Savings | D39: GBP | E39: 103000 | F39: 56650 | G39: 33990 | H39: =TRUE() -> 1 | I39: =VLOOKUP(D39,Assumptions!$H$4:$I$5,2,FALSE()) -> 1.15 | J39: =MATCH(C39,Assumptions!$K$4:$K$6,0) -> 3 | K39: =INDEX(Assumptions!$L$4:$L$6,J39) -> 0.55 | L39: =IF(H39,ROUND(E39*K39,2),Assumptions!$B$11) -> 56650 | M39: =ABS(F39-L39) -> 0 | N39: =INT(E39/Assumptions!$B$12) -> 1
A40: SYN-0037 | B40: Aurora Mutual Life SE (synthetic) | C40: Term Life | D40: EUR | E40: 488000 | F40: 302560 | G40: 181536 | H40: =TRUE() -> 1 | I40: =VLOOKUP(D40,Assumptions!$H$4:$I$5,2,FALSE()) -> 1 | J40: =MATCH(C40,Assumptions!$K$4:$K$6,0) -> 1 | K40: =INDEX(Assumptions!$L$4:$L$6,J40) -> 0.62 | L40: =IF(H40,ROUND(E40*K40,2),Assumptions!$B$11) -> 302560 | M40: =ABS(F40-L40) -> 0 | N40: =INT(E40/Assumptions!$B$12) -> 4
A41: SYN-0038 | B41: Aurora Mutual Life SE (synthetic) | C41: Annuity | D41: EUR | E41: 181000 | F41: 126700 | G41: 76020 | H41: =TRUE() -> 1 | I41: =VLOOKUP(D41,Assumptions!$H$4:$I$5,2,FALSE()) -> 1 | J41: =MATCH(C41,Assumptions!$K$4:$K$6,0) -> 2 | K41: =INDEX(Assumptions!$L$4:$L$6,J41) -> 0.7 | L41: =IF(H41,ROUND(E41*K41,2),Assumptions!$B$11) -> 126700 | M41: =ABS(F41-L41) -> 0 | N41: =INT(E41/Assumptions!$B$12) -> 1
A42: SYN-0039 | B42: Aurora Mutual Life SE (synthetic) | C42: Savings | D42: EUR | E42: 457000 | F42: 251350 | G42: 150810 | H42: =TRUE() -> 1 | I42: =VLOOKUP(D42,Assumptions!$H$4:$I$5,2,FALSE()) -> 1 | J42: =MATCH(C42,Assumptions!$K$4:$K$6,0) -> 3 | K42: =INDEX(Assumptions!$L$4:$L$6,J42) -> 0.55 | L42: =IF(H42,ROUND(E42*K42,2),Assumptions!$B$11) -> 251350 | M42: =ABS(F42-L42) -> 0 | N42: =INT(E42/Assumptions!$B$12) -> 4
A43: SYN-0040 | B43: Aurora Mutual Life SE (synthetic) | C43: Term Life | D43: GBP | E43: 316000 | F43: 195920 | G43: 117552 | H43: =TRUE() -> 1 | I43: =VLOOKUP(D43,Assumptions!$H$4:$I$5,2,FALSE()) -> 1.15 | J43: =MATCH(C43,Assumptions!$K$4:$K$6,0) -> 1 | K43: =INDEX(Assumptions!$L$4:$L$6,J43) -> 0.62 | L43: =IF(H43,ROUND(E43*K43,2),Assumptions!$B$11) -> 195920 | M43: =ABS(F43-L43) -> 0 | N43: =INT(E43/Assumptions!$B$12) -> 3
A44: SYN-0041 | B44: Aurora Mutual Life SE (synthetic) | C44: Annuity | D44: EUR | E44: 274000 | F44: 191800 | G44: 115080 | H44: =TRUE() -> 1 | I44: =VLOOKUP(D44,Assumptions!$H$4:$I$5,2,FALSE()) -> 1 | J44: =MATCH(C44,Assumptions!$K$4:$K$6,0) -> 2 | K44: =INDEX(Assumptions!$L$4:$L$6,J44) -> 0.7 | L44: =IF(H44,ROUND(E44*K44,2),Assumptions!$B$11) -> 191800 | M44: =ABS(F44-L44) -> 0 | N44: =INT(E44/Assumptions!$B$12) -> 2
A45: SYN-0042 | B45: Aurora Mutual Life SE (synthetic) | C45: Savings | D45: EUR | E45: 242000 | F45: 133100 | G45: 79860 | H45: =TRUE() -> 1 | I45: =VLOOKUP(D45,Assumptions!$H$4:$I$5,2,FALSE()) -> 1 | J45: =MATCH(C45,Assumptions!$K$4:$K$6,0) -> 3 | K45: =INDEX(Assumptions!$L$4:$L$6,J45) -> 0.55 | L45: =IF(H45,ROUND(E45*K45,2),Assumptions!$B$11) -> 133100 | M45: =ABS(F45-L45) -> 0 | N45: =INT(E45/Assumptions!$B$12) -> 2
A46: SYN-0043 | B46: Aurora Mutual Life SE (synthetic) | C46: Term Life | D46: EUR | E46: 179000 | F46: 110980 | G46: 66588 | H46: =TRUE() -> 1 | I46: =VLOOKUP(D46,Assumptions!$H$4:$I$5,2,FALSE()) -> 1 | J46: =MATCH(C46,Assumptions!$K$4:$K$6,0) -> 1 | K46: =INDEX(Assumptions!$L$4:$L$6,J46) -> 0.62 | L46: =IF(H46,ROUND(E46*K46,2),Assumptions!$B$11) -> 110980 | M46: =ABS(F46-L46) -> 0 | N46: =INT(E46/Assumptions!$B$12) -> 1
...

Sheet ReserveRollforward
A1: Reserve roll-forward by synthetic cohort
A2: Amounts in EUR for 2025-Q4
A3: Cohort ID | B3: Opening reserve | C3: Claims / service movement | D3: Expense movement | E3: Interest accretion | F3: Assumption strengthening | G3: FX movement | H3: Closing reserve | I3: Ceiling control | J3: Floor control | K3: Rounded up | L3: Rounded down
A4: SYN-0001 | B4: =ROUND(CohortData!G4*CohortData!I4,2) -> 158844 | C4: =ROUND(CohortData!L4*Assumptions!$B$4*CohortData!I4,2) -> 21179.2 | D4: =ROUND(CohortData!E4*Assumptions!$B$5*CohortData!I4,2) -> 8540 | E4: =ROUND(B4*0.035,2) -> 5559.54 | F4: =ROUND(B4*Assumptions!$B$6,2) -> 2382.66 | G4: =ROUND(CohortData!G4*CohortData!I4-CohortData!G4*Assumptions!$B$7,2) -> 0 | H4: =SUM(B4:E4,F4:G4) -> 196505.4 | I4: =CEILING(H4,Assumptions!$B$8) -> 196600 | J4: =FLOOR(H4,Assumptions!$B$8) -> 196500 | K4: =ROUNDUP(H4,Assumptions!$B$9) -> 196506 | L4: =ROUNDDOWN(H4,Assumptions!$B$10) -> 196505
A5: SYN-0002 | B5: =ROUND(CohortData!G5*CohortData!I5,2) -> 65940 | C5: =ROUND(CohortData!L5*Assumptions!$B$4*CohortData!I5,2) -> 8792 | D5: =ROUND(CohortData!E5*Assumptions!$B$5*CohortData!I5,2) -> 3140 | E5: =ROUND(B5*Assumptions!$B$3,2) -> 2307.9 | F5: =ROUND(B5*Assumptions!$B$6,2) -> 989.1 | G5: =ROUND(CohortData!G5*CohortData!I5-CohortData!G5*Assumptions!$B$7,2) -> 0 | H5: =SUM(B5:E5,F5:G5) -> 81169 | I5: =CEILING(H5,Assumptions!$B$8) -> 81200 | J5: =FLOOR(H5,Assumptions!$B$8) -> 81100 | K5: =ROUNDUP(H5,Assumptions!$B$9) -> 81169 | L5: =ROUNDDOWN(H5,Assumptions!$B$10) -> 81169
A6: SYN-0003 | B6: =ROUND(CohortData!G6*CohortData!I6,2) -> 36960 | C6: =ROUND(CohortData!L6*Assumptions!$B$4*CohortData!I6,2) -> 4928 | D6: =ROUND(CohortData!E6*Assumptions!$B$5*CohortData!I6,2) -> 2240 | E6: =ROUND(B6*Assumptions!$B$3,2) -> 1293.6 | F6: =ROUND(B6*Assumptions!$B$6,2) -> 554.4 | G6: =ROUND(CohortData!G6*CohortData!I6-CohortData!G6*Assumptions!$B$7,2) -> 0 | H6: =SUM(B6:E6,F6:G6) -> 45976 | I6: =CEILING(H6,Assumptions!$B$8) -> 46000 | J6: =FLOOR(H6,Assumptions!$B$8) -> 45900 | K6: =ROUNDUP(H6,Assumptions!$B$9) -> 45976 | L6: =ROUNDDOWN(H6,Assumptions!$B$10) -> 45976
A7: SYN-0004 | B7: =ROUND(CohortData!G7*CohortData!I7,2) -> 204916.2 | C7: =ROUND(CohortData!L7*Assumptions!$B$4*CohortData!I7,2) -> 27322.16 | D7: =ROUND(CohortData!E7*Assumptions!$B$5*CohortData!I7,2) -> 11017 | E7: =ROUND(B7*Assumptions!$B$3,2) -> 7172.07 | F7: =ROUND(B7*Assumptions!$B$6,2) -> 3073.74 | G7: =ROUND(CohortData!G7*CohortData!I7-CohortData!G7*Assumptions!$B$7,2) -> 26728.2 | H7: =SUM(B7:E7,F7:G7) -> 280229.37 | I7: =CEILING(H7,Assumptions!$B$8) -> 280300 | J7: =FLOOR(H7,Assumptions!$B$8) -> 280200 | K7: =ROUNDUP(H7,Assumptions!$B$9) -> 280230 | L7: =ROUNDDOWN(H7,Assumptions!$B$10) -> 280229
A8: SYN-0005 | B8: =ROUND(CohortData!G8*CohortData!I8,2) -> 100800 | C8: =ROUND(CohortData!L8*Assumptions!$B$4*CohortData!I8,2) -> 13440 | D8: =ROUND(CohortData!E8*Assumptions!$B$5*CohortData!I8,2) -> 4800 | E8: =ROUND(B8*Assumptions!$B$3,2) -> 3528 | F8: =ROUND(B8*Assumptions!$B$6,2) -> 1512 | G8: =ROUND(CohortData!G8*CohortData!I8-CohortData!G8*Assumptions!$B$7,2) -> 0 | H8: =SUM(B8:E8,F8:G8) -> 124080 | I8: =CEILING(H8,Assumptions!$B$8) -> 124100 | J8: =FLOOR(H8,Assumptions!$B$8) -> 124000 | K8: =ROUNDUP(H8,Assumptions!$B$9) -> 124080 | L8: =ROUNDDOWN(H8,Assumptions!$B$10) -> 124080
A9: SYN-0006 | B9: =ROUND(CohortData!G9*CohortData!I9,2) -> 74250 | C9: =ROUND(CohortData!L9*Assumptions!$B$4*CohortData!I9,2) -> 9900 | D9: =ROUND(CohortData!E9*Assumptions!$B$5*CohortData!I9,2) -> 4500 | E9: =ROUND(B9*Assumptions!$B$3,2) -> 2598.75 | F9: =ROUND(B9*Assumptions!$B$6,2) -> 1113.75 | G9: =ROUND(CohortData!G9*CohortData!I9-CohortData!G9*Assumptions!$B$7,2) -> 0 | H9: =SUM(B9:E9,F9:G9) -> 92362.5 | I9: =CEILING(H9,Assumptions!$B$8) -> 92400 | J9: =FLOOR(H9,Assumptions!$B$8) -> 92300 | K9: =ROUNDUP(H9,Assumptions!$B$9) -> 92363 | L9: =ROUNDDOWN(H9,Assumptions!$B$10) -> 92362
A10: SYN-0007 | B10: =ROUND(CohortData!G10*CohortData!I10,2) -> 79608 | C10: =ROUND(CohortData!L10*Assumptions!$B$4*CohortData!I10,2) -> 10614.4 | D10: =ROUND(CohortData!E10*Assumptions!$B$5*CohortData!I10,2) -> 4280 | E10: =ROUND(B10*Assumptions!$B$3,2) -> 2786.28 | F10: =ROUND(B10*Assumptions!$B$6,2) -> 1194.12 | G10: =ROUND(CohortData!G10*CohortData!I10-CohortData!G10*Assumptions!$B$7,2) -> 0 | H10: =SUM(B10:E10,F10:G10) -> 98482.8 | I10: =CEILING(H10,Assumptions!$B$8) -> 98500 | J10: =FLOOR(H10,Assumptions!$B$8) -> 98400 | K10: =ROUNDUP(H10,Assumptions!$B$9) -> 98483 | L10: =ROUNDDOWN(H10,Assumptions!$B$10) -> 98482
A11: SYN-0008 | B11: =ROUND(CohortData!G11*CohortData!I11,2) -> 82593 | C11: =ROUND(CohortData!L11*Assumptions!$B$4*CohortData!I11,2) -> 11012.4 | D11: =ROUND(CohortData!E11*Assumptions!$B$5*CohortData!I11,2) -> 3933 | E11: =ROUND(B11*Assumptions!$B$3,2) -> 2890.76 | F11: =ROUND(B11*Assumptions!$B$6,2) -> 1238.9 | G11: =ROUND(CohortData!G11*CohortData!I11-CohortData!G11*Assumptions!$B$7,2) -> 10773 | H11: =SUM(B11:E11,F11:G11) -> 112441.06 | I11: =CEILING(H11,Assumptions!$B$8) -> 112500 | J11: =FLOOR(H11,Assumptions!$B$8) -> 112400 | K11: =ROUNDUP(H11,Assumptions!$B$9) -> 112442 | L11: =ROUNDDOWN(H11,Assumptions!$B$10) -> 112441
A12: SYN-0009 | B12: =ROUND(CohortData!G12*CohortData!I12,2) -> 157410 | C12: =ROUND(CohortData!L12*Assumptions!$B$4*CohortData!I12,2) -> 20988 | D12: =ROUND(CohortData!E12*Assumptions!$B$5*CohortData!I12,2) -> 9540 | E12: =ROUND(B12*Assumptions!$B$3,2) -> 5509.35 | F12: =ROUND(B12*Assumptions!$B$6,2) -> 2361.15 | G12: =ROUND(CohortData!G12*CohortData!I12-CohortData!G12*Assumptions!$B$7,2) -> 0 | H12: =SUM(B12:E12,F12:G12) -> 195808.5 | I12: =CEILING(H12,Assumptions!$B$8) -> 195900 | J12: =FLOOR(H12,Assumptions!$B$8) -> 195800 | K12: =ROUNDUP(H12,Assumptions!$B$9) -> 195809 | L12: =ROUNDDOWN(H12,Assumptions!$B$10) -> 195808
A13: SYN-0010 | B13: =ROUND(CohortData!G13*CohortData!I13,2) -> 56544 | C13: =ROUND(CohortData!L13*Assumptions!$B$4*CohortData!I13,2) -> 7539.2 | D13: =ROUND(CohortData!E13*Assumptions!$B$5*CohortData!I13,2) -> 3040 | E13: =ROUND(B13*Assumptions!$B$3,2) -> 1979.04 | F13: =ROUND(B13*Assumptions!$B$6,2) -> 848.16 | G13: =ROUND(CohortData!G13*CohortData!I13-CohortData!G13*Assumptions!$B$7,2) -> 0 | H13: =SUM(B13:E13,F13:G13) -> 69950.4 | I13: =CEILING(H13,Assumptions!$B$8) -> 70000 | J13: =FLOOR(H13,Assumptions!$B$8) -> 69900 | K13: =ROUNDUP(H13,Assumptions!$B$9) -> 69951 | L13: =ROUNDDOWN(H13,Assumptions!$B$10) -> 69950
A14: SYN-0011 | B14: =ROUND(CohortData!G14*CohortData!I14,2) -> 187320 | C14: =ROUND(CohortData!L14*Assumptions!$B$4*CohortData!I14,2) -> 24976 | D14: =ROUND(CohortData!E14*Assumptions!$B$5*CohortData!I14,2) -> 8920 | E14: =ROUND(B14*Assumptions!$B$3,2) -> 6556.2 | F14: =ROUND(B14*Assumptions!$B$6,2) -> 2809.8 | G14: =ROUND(CohortData!G14*CohortData!I14-CohortData!G14*Assumptions!$B$7,2) -> 0 | H14: =SUM(B14:E14,F14:G14) -> 230582 | I14: =CEILING(H14,Assumptions!$B$8) -> 230600 | J14: =FLOOR(H14,Assumptions!$B$8) -> 230500 | K14: =ROUNDUP(H14,Assumptions!$B$9) -> 230582 | L14: =ROUNDDOWN(H14,Assumptions!$B$10) -> 230582
A15: SYN-0012 | B15: =ROUND(CohortData!G15*CohortData!I15,2) -> 181780.5 | C15: =ROUND(CohortData!L15*Assumptions!$B$4*CohortData!I15,2) -> 24237.4 | D15: =ROUND(CohortData!E15*Assumptions!$B$5*CohortData!I15,2) -> 11017 | E15: =ROUND(B15*Assumptions!$B$3,2) -> 6362.32 | F15: =ROUND(B15*Assumptions!$B$6,2) -> 2726.71 | G15: =ROUND(CohortData!G15*CohortData!I15-CohortData!G15*Assumptions!$B$7,2) -> 23710.5 | H15: =SUM(B15:E15,F15:G15) -> 249834.43 | I15: =CEILING(H15,Assumptions!$B$8) -> 249900 | J15: =FLOOR(H15,Assumptions!$B$8) -> 249800 | K15: =ROUNDUP(H15,Assumptions!$B$9) -> 249835 | L15: =ROUNDDOWN(H15,Assumptions!$B$10) -> 249834
A16: SYN-0013 | B16: =ROUND(CohortData!G16*CohortData!I16,2) -> 140988 | C16: =ROUND(CohortData!L16*Assumptions!$B$4*CohortData!I16,2) -> 18798.4 | D16: =ROUND(CohortData!E16*Assumptions!$B$5*CohortData!I16,2) -> 7580 | E16: =ROUND(B16*Assumptions!$B$3,2) -> 4934.58 | F16: =ROUND(B16*Assumptions!$B$6,2) -> 2114.82 | G16: =ROUND(CohortData!G16*CohortData!I16-CohortData!G16*Assumptions!$B$7,2) -> 0 | H16: =SUM(B16:E16,F16:G16) -> 174415.8 | I16: =CEILING(H16,Assumptions!$B$8) -> 174500 | J16: =FLOOR(H16,Assumptions!$B$8) -> 174400 | K16: =ROUNDUP(H16,Assumptions!$B$9) -> 174416 | L16: =ROUNDDOWN(H16,Assumptions!$B$10) -> 174415
... A603: SYN-0600 | B603: =ROUND(CohortData!G603*CohortData!I603,2) -> 62617.5 | C603: =ROUND(CohortData!L603*Assumptions!$B$4*CohortData!I603,2) -> 8349 | D603: =ROUND(CohortData!E603*Assumptions!$B$5*CohortData!I603,2) -> 3795 | E603: =ROUND(B603*Assumptions!$B$3,2) -> 2191.61 | F603: =ROUND(B603*Assumptions!$B$6,2) -> 939.26 | G603: =ROUND(CohortData!G603*CohortData!I603-CohortData!G603*Assumptions!$B$7,2) -> 8167.5 | H603: =SUM(B603:E603,F603:G603) -> 86059.87 | I603: =CEILING(H603,Assumptions!$B$8) -> 86100 | J603: =FLOOR(H603,Assumptions!$B$8) -> 86000 | K603: =ROUNDUP(H603,Assumptions!$B$9) -> 86060 | L603: =ROUNDDOWN(H603,Assumptions!$B$10) -> 86059

Sheet Aggregation
A1: Product aggregation and distribution checks
A2: Synthetic portfolio summary for 2025-Q4
A3: Product | B3: Cohort count | C3: Included count | D3: Opening reserve | E3: Service movement | F3: Average closing | G3: Average included closing | H3: Minimum closing | I3: Maximum closing | J3: Closing reserve
A4: Term Life | B4: =COUNTIF(CohortData!$C$4:$C$603,A4) -> 200 | C4: =COUNTIFS(CohortData!$C$4:$C$603,A4,CohortData!$H$4:$H$603,TRUE()) -> 188 | D4: =SUMIF(CohortData!$C$4:$C$603,A4,ReserveRollforward!$B$4:$B$603) -> 22664156 | E4: =SUMIFS(ReserveRollforward!$C$4:$C$603,CohortData!$C$4:$C$603,A4,CohortData!$H$4:$H$603,TRUE()) -> 2828073 | F4: =AVERAGEIF(CohortData!$C$4:$C$603,A4,ReserveRollforward!$H$4:$H$603) -> 143220.84 | G4: =AVERAGEIFS(ReserveRollforward!$H$4:$H$603,CohortData!$C$4:$C$603,A4,CohortData!$H$4:$H$603,TRUE()) -> 143532.42 | H4: =_xlfn.MINIFS(ReserveRollforward!$H$4:$H$603,CohortData!$C$4:$C$603,A4) -> 46020 | I4: =_xlfn.MAXIFS(ReserveRollforward!$H$4:$H$603,CohortData!$C$4:$C$603,A4) -> 286079.67 | J4: =SUMIF(CohortData!$C$4:$C$603,A4,ReserveRollforward!$H$4:$H$603) -> 28644167
A5: Annuity | B5: =COUNTIF(CohortData!$C$4:$C$603,A5) -> 200 | C5: =COUNTIFS(CohortData!$C$4:$C$603,A5,CohortData!$H$4:$H$603,TRUE()) -> 188 | D5: =SUMIF(CohortData!$C$4:$C$603,A5,ReserveRollforward!$B$4:$B$603) -> 25773993 | E5: =SUMIFS(ReserveRollforward!$C$4:$C$603,CohortData!$C$4:$C$603,A5,CohortData!$H$4:$H$603,TRUE()) -> 3246485.2 | F5: =AVERAGEIF(CohortData!$C$4:$C$603,A5,ReserveRollforward!$H$4:$H$603) -> 162348.02 | G5: =AVERAGEIFS(ReserveRollforward!$H$4:$H$603,CohortData!$C$4:$C$603,A5,CohortData!$H$4:$H$603,TRUE()) -> 164128.16 | H5: =_xlfn.MINIFS(ReserveRollforward!$H$4:$H$603,CohortData!$C$4:$C$603,A5) -> 51700 | I5: =_xlfn.MAXIFS(ReserveRollforward!$H$4:$H$603,CohortData!$C$4:$C$603,A5) -> 328775 | J5: =SUMIF(CohortData!$C$4:$C$603,A5,ReserveRollforward!$H$4:$H$603) -> 32469604
A6: Savings | B6: =COUNTIF(CohortData!$C$4:$C$603,A6) -> 200 | C6: =COUNTIFS(CohortData!$C$4:$C$603,A6,CohortData!$H$4:$H$603,TRUE()) -> 189 | D6: =SUMIF(CohortData!$C$4:$C$603,A6,ReserveRollforward!$B$4:$B$603) -> 20260466 | E6: =SUMIFS(ReserveRollforward!$C$4:$C$603,CohortData!$C$4:$C$603,A6,CohortData!$H$4:$H$603,TRUE()) -> 2541275 | F6: =AVERAGEIF(CohortData!$C$4:$C$603,A6,ReserveRollforward!$H$4:$H$603) -> 128715.23 | G6: =AVERAGEIFS(ReserveRollforward!$H$4:$H$603,CohortData!$C$4:$C$603,A6,CohortData!$H$4:$H$603,TRUE()) -> 128941.87 | H6: =_xlfn.MINIFS(ReserveRollforward!$H$4:$H$603,CohortData!$C$4:$C$603,A6) -> 42692 | I6: =_xlfn.MAXIFS(ReserveRollforward!$H$4:$H$603,CohortData!$C$4:$C$603,A6) -> 252963.87 | J6: =SUMIF(CohortData!$C$4:$C$603,A6,ReserveRollforward!$H$4:$H$603) -> 25743046
A8: Portfolio total | B8: =SUM(B4:B6) -> 600 | C8: =SUM(C4:C6) -> 565 | D8: =SUM(D4:D6) -> 68698614 | E8: =SUM(E4:E6) -> 8615833.2 | F8: =SUM(F4:F6) -> 434284.09 | G8: =SUM(G4:G6) -> 436602.45 | H8: =SUM(H4:H6) -> 140412 | I8: =SUM(I4:I6) -> 867818.54 | J8: =SUM(J4:J4,J6:J6) -> 86856818

Sheet AccountingBridge
A1: Accounting bridge outputs
A2: Signed balances: credits are negative; all figures are synthetic.
A3: Account | B3: Output label | C3: Signed balance (EUR)
A4: SYN-2100 | B4: Opening reserve | C4: =-SUM(ReserveRollforward!B4:B603) -> -68698614
A5: SYN-2110 | B5: Claims and service movements | C5: =-SUM(ReserveRollforward!C4:C603) -> -8615833.2
A6: SYN-2120 | B6: Assumption strengthening amount | C6: =-SUM(ReserveRollforward!F4:F603) -> -1030479.4
A7: SYN-2130 | B7: FX movement | C7: =-SUM(ReserveRollforward!G4:G603) -> -2433696.3
A8: SYN-2140 | B8: Closing reserve | C8: =-SUM(ReserveRollforward!H4:H603) -> -86856818
A9: SYN-2199 | B9: Signed accounting balance | C9: =SUM(C4:C8)+OFFSET(Controls!B4,0,0) -> -1.6763544e+08
A10: SYN-2150 | B10: Expense movement output | C10: =-SUM(ReserveRollforward!D4:D603) -> -3673743

Sheet Controls
A1: Independent workbook controls
A2: A zero value is expected for each calculation.
A3: Control | B3: Difference (EUR)
A4: Closing reserve to roll-forward | B4: =AccountingBridge!C8+SUM(ReserveRollforward!H4:H603) -> 0
A5: Opening reserve to roll-forward | B5: =AccountingBridge!C4+SUM(ReserveRollforward!B4:B603) -> 0
A6: Accounting bridge signed total | B6: =AccountingBridge!C9-SUM(AccountingBridge!C4:C8) -> 0
A7: Aggregation closing reserve | B7: =ROUND(Aggregation!J8-SUM(ReserveRollforward!H4:H603),2) -> 0
A8: Absolute closing difference | B8: =ABS(B4) -> 0

Sheet DemoGuide
A1: Demonstration guide
A2: Scope | B2: Spreadsheet reconstruction and financial reconciliation around a synthetic IFRS 17-related process.
A3: Boundary | B3: This workbook does not implement or validate the full IFRS 17 methodology and is not an audit opinion.
A4: Synthetic data | B4: All entities, cohorts, accounts and amounts are fictional.
A5: Gate 2 authoritative output | B5: AccountingBridge!C9
A7: Cell | B7: Hand-checkable output | C7: Expected signed value (EUR)
A8: AccountingBridge!C4 | B8: Opening reserve | C8: -68698614
A9: AccountingBridge!C5 | B9: Claims and service movements | C9: -8615833.2
A10: AccountingBridge!C6 | B10: Assumption strengthening amount | C10: -1030479.4
A11: AccountingBridge!C7 | B11: FX movement | C11: -2433696.3
A12: AccountingBridge!C8 | B12: Closing reserve | C12: -86856818
A13: AccountingBridge!C9 | B13: Signed accounting balance | C13: -1.6763544e+08
A15: Demonstration sequence
A16: 1 | B16: Confirm entity, period, currency, basis, workbook hash and accounting reference context at Gate 1.
A17: 2 | B17: Review every finding and designate AccountingBridge!C9 at Gate 2.
A18: 3 | B18: Approve the proposed accounting mapping and set both materiality thresholds at Gate 3.
A19: 4 | B19: Create the named approval record at Gate 4; only then generate the PDF.
