Workbook

Sheet Inputs
A1: Synthetic formula-qualification inputs
A2: All values are fictional and exist only to exercise the reconstruction engine.
A3: Category | B3: Amount | C3: Region | D3: Included | E3: Lookup key | F3: Rate
A4: Motor | B4: 10 | C4: North | D4: TRUE | E4: Motor | F4: 1.1
A5: Property | B5: 20 | C5: South | D5: FALSE | E5: Property | F5: 1.2
A6: Motor | B6: -5 | C6: North | D6: TRUE | E6: Liability | F6: 1.3
A7: Liability | C7: North | D7: FALSE
A8: Motor | B8: 0 | C8: South | D8: TRUE
B9: text inside numeric range

Sheet Qualification
A1: Production-path formula acceptance cases
A2: Each result is recalculated by LibreOffice and independently reconstructed in Python.
A3: Case | B3: Formula result | C3: Expected value | D3: Expected state | E3: Purpose
A4: sum_mixed_range | B4: =SUM(Inputs!$B$4:$B$8) | C4: 25 | D4: complete | E4: Blank/text ignored; zero retained
A5: abs_negative | B5: =ABS(Inputs!$B$6) | C5: 5 | D5: complete
A6: int_negative | B6: =INT(-1.2) | C6: -2 | D6: complete
A7: round_positive_half | B7: =ROUND(2.5,0) | C7: 3 | D7: complete | E7: Excel half away from zero
A8: round_negative_half | B8: =ROUND(-2.5,0) | C8: -3 | D8: complete | E8: Excel half away from zero
A9: roundup_negative | B9: =ROUNDUP(-1.21,1) | C9: -1.3 | D9: complete
A10: rounddown_negative | B10: =ROUNDDOWN(-1.29,1) | C10: -1.2 | D10: complete
A11: ceiling_positive | B11: =CEILING(2.1,0.5) | C11: 2.5 | D11: complete
A12: floor_positive | B12: =FLOOR(2.9,0.5) | C12: 2.5 | D12: complete
A13: sumif_text | B13: =SUMIF(Inputs!$A$4:$A$8,"Motor",Inputs!$B$4:$B$8) | C13: 5 | D13: complete
A14: sumifs_text_region | B14: =SUMIFS(Inputs!$B$4:$B$8,Inputs!$A$4:$A$8,"Motor",Inputs!$C$4:$C$8,"North") | C14: 5 | D14: complete
A15: countif_text | B15: =COUNTIF(Inputs!$A$4:$A$8,"Motor") | C15: 3 | D15: complete
A16: countifs_boolean | B16: =COUNTIFS(Inputs!$A$4:$A$8,"Motor",Inputs!$D$4:$D$8,TRUE()) | C16: 3 | D16: complete | E16: TRUE() boolean call in a criteria function
A17: averageif_blank_zero | B17: =AVERAGEIF(Inputs!$A$4:$A$8,"Motor",Inputs!$B$4:$B$8) | C17: 1.6666667 | D17: complete | E17: A literal zero contributes to the denominator
A18: averageifs_text_region | B18: =AVERAGEIFS(Inputs!$B$4:$B$8,Inputs!$A$4:$A$8,"Motor",Inputs!$C$4:$C$8,"North") | C18: 2.5 | D18: complete
A19: minifs_text | B19: =_xlfn.MINIFS(Inputs!$B$4:$B$8,Inputs!$A$4:$A$8,"Motor") | C19: -5 | D19: complete
A20: maxifs_text | B20: =_xlfn.MAXIFS(Inputs!$B$4:$B$8,Inputs!$A$4:$A$8,"Motor") | C20: 10 | D20: complete
A21: if_true_literal | B21: =IF(TRUE,11,22) | C21: 11 | D21: complete
A22: if_false_literal | B22: =IF(FALSE,11,22) | C22: 22 | D22: complete
A23: if_true_call | B23: =IF(TRUE(),11,22) | C23: 11 | D23: complete
A24: if_false_call | B24: =IF(FALSE(),11,22) | C24: 22 | D24: complete
A25: vlookup_exact | B25: =VLOOKUP("Property",Inputs!$E$4:$F$6,2,FALSE()) | C25: 1.2 | D25: complete
A26: match_exact | B26: =MATCH("Liability",Inputs!$E$4:$E$6,0) | C26: 3 | D26: complete
A27: index_scalar | B27: =INDEX(Inputs!$F$4:$F$6,2) | C27: 1.2 | D27: complete
A28: index_match_nested | B28: =INDEX(Inputs!$F$4:$F$6,MATCH("Liability",Inputs!$E$4:$E$6,0)) | C28: 1.3 | D28: complete
A29: nested_round_sumif | B29: =ROUND(SUMIF(Inputs!$A$4:$A$8,"Motor",Inputs!$B$4:$B$8),2) | C29: 5 | D29: complete
A30: cross_tab_range | B30: =SUM('Cross Tab'!$B$3:$B$5) | C30: 20 | D30: complete
A31: ordinary_arithmetic | B31: =(Inputs!$B$4+Inputs!$B$5)*2/3 | C31: 20 | D31: complete
A32: vlookup_approximate_unsupported | B32: =VLOOKUP("Property",Inputs!$E$4:$F$6,2,TRUE()) | D32: partial | E32: Approximate lookup must fail closed
A33: match_approximate_unsupported | B33: =MATCH("Property",Inputs!$E$4:$E$6,1) | D33: partial | E33: Approximate MATCH must fail closed
A34: index_array_unsupported | B34: =INDEX(Inputs!$B$4:$B$8,0) | D34: partial | E34: Array result must not be silently reduced to a scalar
A35: offset_unsupported | B35: =OFFSET(Inputs!$B$4,1,0) | D35: partial | E35: Function outside the catalogue
A36: and_all_true | B36: =IF(AND(TRUE,TRUE,TRUE),1,0) | C36: 1 | D36: complete
A37: and_one_false | B37: =IF(AND(TRUE,FALSE,TRUE),1,0) | C37: 0 | D37: complete
A38: or_one_true | B38: =IF(OR(FALSE,TRUE,FALSE),1,0) | C38: 1 | D38: complete
A39: or_all_false | B39: =IF(OR(FALSE,FALSE,FALSE),1,0) | C39: 0 | D39: complete
A40: sumproduct_2d | B40: =SUMPRODUCT(Inputs!$B$4:$B$6,Inputs!$F$4:$F$6) | C40: 28.5 | D40: complete
...

Sheet Cross Tab
A1: Cross-tab range inputs
A2: Item | B2: Amount
A3: A | B3: 4
A4: B | B4: 6
A5: C | B5: 10

Sheet Errors
A1: Deliberate spreadsheet error evidence
A2: These errors are parser evidence, not successful reconstruction cases.
A3: Error type | B3: Formula
A4: #N/A | B4: =NA()
A5: #VALUE! | B5: =1+"text"
A6: #DIV/0! | B6: =1/0

Sheet Guide
A1: Qualification evidence guide
A2: Scope | B2: Formula reconstruction only; no actuarial methodology validation or audit opinion.
A3: Target engine | B3: LibreOffice headless recalculation; Microsoft Excel compatibility is not tested.
A4: Generated by | B4: scripts/generate_qualification_workbook.py
A5: Recalculated by | B5: scripts/recalculate_with_libreoffice.sh
A6: Acceptance data | B6: tests/fixtures/qualification_expected.json
